2024-12-03 22:51:34,714 INFO    MainThread:29527 [wandb_setup.py:_flush():79] Current SDK version is 0.18.7
2024-12-03 22:51:34,714 INFO    MainThread:29527 [wandb_setup.py:_flush():79] Configure stats pid to 29527
2024-12-03 22:51:34,714 INFO    MainThread:29527 [wandb_setup.py:_flush():79] Loading settings from /home/aa12938/.config/wandb/settings
2024-12-03 22:51:34,714 INFO    MainThread:29527 [wandb_setup.py:_flush():79] Loading settings from /home/aa12938/DL_Final_Proj/wandb/settings
2024-12-03 22:51:34,714 INFO    MainThread:29527 [wandb_setup.py:_flush():79] Loading settings from environment variables: {}
2024-12-03 22:51:34,716 INFO    MainThread:29527 [wandb_setup.py:_flush():79] Applying setup settings: {'mode': None, '_disable_service': None}
2024-12-03 22:51:34,716 INFO    MainThread:29527 [wandb_setup.py:_flush():79] Inferring run settings from compute environment: {'program': '<python with no main file>'}
2024-12-03 22:51:34,716 INFO    MainThread:29527 [wandb_setup.py:_flush():79] Applying login settings: {}
2024-12-03 22:51:34,716 INFO    MainThread:29527 [wandb_init.py:_log_setup():533] Logging user logs to /home/aa12938/DL_Final_Proj/wandb/run-20241203_225134-gzes3lhw/logs/debug.log
2024-12-03 22:51:34,717 INFO    MainThread:29527 [wandb_init.py:_log_setup():534] Logging internal logs to /home/aa12938/DL_Final_Proj/wandb/run-20241203_225134-gzes3lhw/logs/debug-internal.log
2024-12-03 22:51:34,717 INFO    MainThread:29527 [wandb_init.py:init():619] calling init triggers
2024-12-03 22:51:34,719 INFO    MainThread:29527 [wandb_init.py:init():626] wandb.init called with sweep_config: {}
config: {}
2024-12-03 22:51:34,719 INFO    MainThread:29527 [wandb_init.py:init():669] starting backend
2024-12-03 22:51:34,719 INFO    MainThread:29527 [wandb_init.py:init():673] sending inform_init request
2024-12-03 22:51:34,729 INFO    MainThread:29527 [backend.py:_multiprocessing_setup():104] multiprocessing start_methods=fork,spawn,forkserver, using: spawn
2024-12-03 22:51:34,729 INFO    MainThread:29527 [wandb_init.py:init():686] backend started and connected
2024-12-03 22:51:34,747 INFO    MainThread:29527 [wandb_init.py:init():781] updated telemetry
2024-12-03 22:51:34,770 INFO    MainThread:29527 [wandb_init.py:init():814] communicating run to backend with 90.0 second timeout
2024-12-03 22:51:34,921 ERROR   MainThread:29527 [wandb_init.py:init():841] encountered error: failed to upsert bucket: returned error 404 Not Found: {"errors":[{"message":"entity your_username not found during upsertBucket","path":["upsertBucket"]}],"data":{"upsertBucket":null}}
2024-12-03 22:51:34,921 ERROR   MainThread:29527 [wandb_init.py:init():1266] error in wandb.init()
Traceback (most recent call last):
  File "/scratch/aa12938/miniconda3/envs/dl-final/lib/python3.9/site-packages/wandb/sdk/wandb_init.py", line 1256, in init
    return wi.init()
  File "/scratch/aa12938/miniconda3/envs/dl-final/lib/python3.9/site-packages/wandb/sdk/wandb_init.py", line 847, in init
    raise error
wandb.errors.errors.CommError: failed to upsert bucket: returned error 404 Not Found: {"errors":[{"message":"entity your_username not found during upsertBucket","path":["upsertBucket"]}],"data":{"upsertBucket":null}}
2024-12-03 22:52:38,307 WARNING MsgRouterThr:29527 [router.py:message_loop():75] message_loop has been closed
